2024-01-20 18:45:56,125 ERROR: Exception on /edit_profile [POST] [in c:\Users\cschm\dev\microblog_vs\.venv\Lib\site-packages\flask\app.py:825]
Traceback (most recent call last):
  File "c:\Users\cschm\dev\microblog_vs\.venv\Lib\site-packages\sqlalchemy\engine\base.py", line 1969, in _exec_single_context
    self.dialect.do_execute(
  File "c:\Users\cschm\dev\microblog_vs\.venv\Lib\site-packages\sqlalchemy\engine\default.py", line 922, in do_execute
    cursor.execute(statement, parameters)
psycopg2.errors.UniqueViolation: duplicate key value violates unique constraint "ix_user_username"
DETAIL:  Key (username)=(admin) already exists.


The above exception was the direct cause of the following exception:

Traceback (most recent call last):
  File "c:\Users\cschm\dev\microblog_vs\.venv\Lib\site-packages\flask\app.py", line 1455, in wsgi_app
    response = self.full_dispatch_request()
               ^^^^^^^^^^^^^^^^^^^^^^^^^^^^
  File "c:\Users\cschm\dev\microblog_vs\.venv\Lib\site-packages\flask\app.py", line 869, in full_dispatch_request
    rv = self.handle_user_exception(e)
         ^^^^^^^^^^^^^^^^^^^^^^^^^^^^^
  File "c:\Users\cschm\dev\microblog_vs\.venv\Lib\site-packages\flask\app.py", line 867, in full_dispatch_request
    rv = self.dispatch_request()
         ^^^^^^^^^^^^^^^^^^^^^^^
  File "c:\Users\cschm\dev\microblog_vs\.venv\Lib\site-packages\flask\app.py", line 852, in dispatch_request
    return self.ensure_sync(self.view_functions[rule.endpoint])(**view_args)
           ^^^^^^^^^^^^^^^^^^^^^^^^^^^^^^^^^^^^^^^^^^^^^^^^^^^^^^^^^^^^^^^^^
  File "c:\Users\cschm\dev\microblog_vs\.venv\Lib\site-packages\flask_login\utils.py", line 290, in decorated_view
    return current_app.ensure_sync(func)(*args, **kwargs)
           ^^^^^^^^^^^^^^^^^^^^^^^^^^^^^^^^^^^^^^^^^^^^^^
  File "c:\Users\cschm\dev\microblog_vs\app_package\route.py", line 90, in edit_profile
    exists = db.session.query(db.session.query(User).filter_by(username=current_user.username).exists()).scalar()
             ^^^^^^^^^^^^^^^^^^^^^^^^^^^^^^^^^^^^^^^^^^^^^^^^^^^^^^^^^^^^^^^^^^^^^^^^^^^^^^^^^^^^^^^^^^^^^^^^^^^^
  File "c:\Users\cschm\dev\microblog_vs\.venv\Lib\site-packages\sqlalchemy\orm\query.py", line 2825, in scalar
    ret = self.one()
          ^^^^^^^^^^
  File "c:\Users\cschm\dev\microblog_vs\.venv\Lib\site-packages\sqlalchemy\orm\query.py", line 2798, in one
    return self._iter().one()  # type: ignore
           ^^^^^^^^^^^^
  File "c:\Users\cschm\dev\microblog_vs\.venv\Lib\site-packages\sqlalchemy\orm\query.py", line 2847, in _iter
    result: Union[ScalarResult[_T], Result[_T]] = self.session.execute(
                                                  ^^^^^^^^^^^^^^^^^^^^^
  File "c:\Users\cschm\dev\microblog_vs\.venv\Lib\site-packages\sqlalchemy\orm\session.py", line 2308, in execute
    return self._execute_internal(
           ^^^^^^^^^^^^^^^^^^^^^^^
  File "c:\Users\cschm\dev\microblog_vs\.venv\Lib\site-packages\sqlalchemy\orm\session.py", line 2169, in _execute_internal
    ) = compile_state_cls.orm_pre_session_exec(
        ^^^^^^^^^^^^^^^^^^^^^^^^^^^^^^^^^^^^^^^
  File "c:\Users\cschm\dev\microblog_vs\.venv\Lib\site-packages\sqlalchemy\orm\context.py", line 551, in orm_pre_session_exec
    session._autoflush()
  File "c:\Users\cschm\dev\microblog_vs\.venv\Lib\site-packages\sqlalchemy\orm\session.py", line 3021, in _autoflush
    raise e.with_traceback(sys.exc_info()[2])
  File "c:\Users\cschm\dev\microblog_vs\.venv\Lib\site-packages\sqlalchemy\orm\session.py", line 3010, in _autoflush
    self.flush()
  File "c:\Users\cschm\dev\microblog_vs\.venv\Lib\site-packages\sqlalchemy\orm\session.py", line 4312, in flush
    self._flush(objects)
  File "c:\Users\cschm\dev\microblog_vs\.venv\Lib\site-packages\sqlalchemy\orm\session.py", line 4447, in _flush
    with util.safe_reraise():
  File "c:\Users\cschm\dev\microblog_vs\.venv\Lib\site-packages\sqlalchemy\util\langhelpers.py", line 146, in __exit__
    raise exc_value.with_traceback(exc_tb)
  File "c:\Users\cschm\dev\microblog_vs\.venv\Lib\site-packages\sqlalchemy\orm\session.py", line 4408, in _flush
    flush_context.execute()
  File "c:\Users\cschm\dev\microblog_vs\.venv\Lib\site-packages\sqlalchemy\orm\unitofwork.py", line 466, in execute
    rec.execute(self)
  File "c:\Users\cschm\dev\microblog_vs\.venv\Lib\site-packages\sqlalchemy\orm\unitofwork.py", line 642, in execute
    util.preloaded.orm_persistence.save_obj(
  File "c:\Users\cschm\dev\microblog_vs\.venv\Lib\site-packages\sqlalchemy\orm\persistence.py", line 85, in save_obj
    _emit_update_statements(
  File "c:\Users\cschm\dev\microblog_vs\.venv\Lib\site-packages\sqlalchemy\orm\persistence.py", line 910, in _emit_update_statements
    c = connection.execute(
        ^^^^^^^^^^^^^^^^^^^
  File "c:\Users\cschm\dev\microblog_vs\.venv\Lib\site-packages\sqlalchemy\engine\base.py", line 1416, in execute
    return meth(
           ^^^^^
  File "c:\Users\cschm\dev\microblog_vs\.venv\Lib\site-packages\sqlalchemy\sql\elements.py", line 517, in _execute_on_connection
    return connection._execute_clauseelement(
           ^^^^^^^^^^^^^^^^^^^^^^^^^^^^^^^^^^
  File "c:\Users\cschm\dev\microblog_vs\.venv\Lib\site-packages\sqlalchemy\engine\base.py", line 1639, in _execute_clauseelement
    ret = self._execute_context(
          ^^^^^^^^^^^^^^^^^^^^^^
  File "c:\Users\cschm\dev\microblog_vs\.venv\Lib\site-packages\sqlalchemy\engine\base.py", line 1848, in _execute_context
    return self._exec_single_context(
           ^^^^^^^^^^^^^^^^^^^^^^^^^^
  File "c:\Users\cschm\dev\microblog_vs\.venv\Lib\site-packages\sqlalchemy\engine\base.py", line 1988, in _exec_single_context
    self._handle_dbapi_exception(
  File "c:\Users\cschm\dev\microblog_vs\.venv\Lib\site-packages\sqlalchemy\engine\base.py", line 2344, in _handle_dbapi_exception
    raise sqlalchemy_exception.with_traceback(exc_info[2]) from e
  File "c:\Users\cschm\dev\microblog_vs\.venv\Lib\site-packages\sqlalchemy\engine\base.py", line 1969, in _exec_single_context
    self.dialect.do_execute(
  File "c:\Users\cschm\dev\microblog_vs\.venv\Lib\site-packages\sqlalchemy\engine\default.py", line 922, in do_execute
    cursor.execute(statement, parameters)
sqlalchemy.exc.IntegrityError: (raised as a result of Query-invoked autoflush; consider using a session.no_autoflush block if this flush is occurring prematurely)
(psycopg2.errors.UniqueViolation) duplicate key value violates unique constraint "ix_user_username"
DETAIL:  Key (username)=(admin) already exists.

[SQL: UPDATE "user" SET username=%(username)s WHERE "user".id = %(user_id)s]
[parameters: {'username': 'admin', 'user_id': 6}]
(Background on this error at: https://sqlalche.me/e/20/gkpj)
2024-01-20 18:48:43,224 INFO: Microblog startup [in c:\Users\cschm\dev\microblog_vs\app_package\__init__.py:53]
2024-01-20 18:49:30,895 ERROR: Exception on /edit_profile [POST] [in c:\Users\cschm\dev\microblog_vs\.venv\Lib\site-packages\flask\app.py:825]
Traceback (most recent call last):
  File "c:\Users\cschm\dev\microblog_vs\.venv\Lib\site-packages\flask\app.py", line 1455, in wsgi_app
    response = self.full_dispatch_request()
               ^^^^^^^^^^^^^^^^^^^^^^^^^^^^
  File "c:\Users\cschm\dev\microblog_vs\.venv\Lib\site-packages\flask\app.py", line 869, in full_dispatch_request
    rv = self.handle_user_exception(e)
         ^^^^^^^^^^^^^^^^^^^^^^^^^^^^^
  File "c:\Users\cschm\dev\microblog_vs\.venv\Lib\site-packages\flask\app.py", line 867, in full_dispatch_request
    rv = self.dispatch_request()
         ^^^^^^^^^^^^^^^^^^^^^^^
  File "c:\Users\cschm\dev\microblog_vs\.venv\Lib\site-packages\flask\app.py", line 852, in dispatch_request
    return self.ensure_sync(self.view_functions[rule.endpoint])(**view_args)
           ^^^^^^^^^^^^^^^^^^^^^^^^^^^^^^^^^^^^^^^^^^^^^^^^^^^^^^^^^^^^^^^^^
  File "c:\Users\cschm\dev\microblog_vs\.venv\Lib\site-packages\flask_login\utils.py", line 290, in decorated_view
    return current_app.ensure_sync(func)(*args, **kwargs)
           ^^^^^^^^^^^^^^^^^^^^^^^^^^^^^^^^^^^^^^^^^^^^^^
  File "c:\Users\cschm\dev\microblog_vs\app_package\route.py", line 90, in edit_profile
    exists = sa.session.query(sa.session.query(User).filter_by(username=current_user.username).exists()).scalar()
             ^^^^^^^^^^
  File "c:\Users\cschm\dev\microblog_vs\.venv\Lib\site-packages\sqlalchemy\__init__.py", line 294, in __getattr__
    raise AttributeError(f"module {__name__!r} has no attribute {name!r}")
AttributeError: module 'sqlalchemy' has no attribute 'session'
2024-01-20 18:56:56,478 INFO: Microblog startup [in c:\Users\cschm\dev\microblog_vs\app_package\__init__.py:53]
2024-01-20 19:00:20,308 INFO: Microblog startup [in c:\Users\cschm\dev\microblog_vs\app_package\__init__.py:53]
2024-01-21 18:39:27,078 INFO: Microblog startup [in c:\Users\cschm\dev\microblog_vs\app_package\__init__.py:53]
2024-01-21 18:40:26,164 INFO: Microblog startup [in c:\Users\cschm\dev\microblog_vs\app_package\__init__.py:53]
2024-01-28 16:29:23,413 INFO: Microblog startup [in c:\Users\cschm\dev\microblog_vs\app_package\__init__.py:53]
2024-01-28 16:42:23,253 INFO: Microblog startup [in c:\Users\cschm\dev\microblog_vs\app_package\__init__.py:53]
2024-01-28 16:48:02,335 INFO: Microblog startup [in c:\Users\cschm\dev\microblog_vs\app_package\__init__.py:53]
2024-01-28 16:56:58,523 INFO: Microblog startup [in c:\Users\cschm\dev\microblog_vs\app_package\__init__.py:53]
2024-01-28 16:59:02,926 INFO: Microblog startup [in c:\Users\cschm\dev\microblog_vs\app_package\__init__.py:53]
2024-02-05 14:58:58,897 INFO: Microblog startup [in c:\Users\cschm\dev\microblog_vs\app_package\__init__.py:53]
2024-02-19 19:24:10,621 INFO: Microblog startup [in c:\Users\cschm\dev\microblog_vs\app_package\__init__.py:53]
2024-02-19 19:26:11,420 INFO: Microblog startup [in c:\Users\cschm\dev\microblog_vs\app_package\__init__.py:53]
2024-02-19 19:34:57,440 INFO: Microblog startup [in c:\Users\cschm\dev\microblog_vs\app_package\__init__.py:53]
2024-02-20 18:29:18,003 INFO: Microblog startup [in c:\Users\cschm\dev\microblog_vs\app_package\__init__.py:55]
